Workbook

Sheet Read_me
A1: Verdict — wishlist survey workbook
A3: What this is
A4: Supporting artefact for Part 3. Interviews stay the qualitative lock. This workbook is the survey database. The live fillable form is /survey/form/ on the case site. Responses tab is the panel for this case.
A6: What is in Responses
A7: Constructed case sample (same method as the six interview write-ups). Cities: Bengaluru, Hyderabad, Delhi, Gurugram, Noida, Coimbatore, plus out-of-target noise (Mumbai, Pune, non-metro, other ages/genders). in_target and q3_code fill by formula.
A9: Host
A10: Live form: case site /survey/form/. Database = this xlsx.
A12: How the pieces fit
A13: 1. Instrument tab = every question. The live form uses the same IDs (S1. … Q3. …).
A14: 2. Responses tab = the case panel evaluators open.
A15: 3. Keep formula columns in_target / q3_code / off_app / legal_lever. Do not overwrite them.
A17: in_target rule
... A27: Analysis — counts that update from in_target / q3_code.

Sheet Instrument
A1: id | B1: section | C1: type | D1: required | E1: title | F1: options | G1: maps_to | H1: skip
A2: C1 | B2: 0. Consent | C2: mcq | D2: TRUE | E2: I understand this is anonymous and I can close the tab anytime. | F2: Yes, continue | G2: Consent
A3: S1 | B3: 1. Screener | C3: mcq | D3: TRUE | E3: Do you currently use the Myntra app or website? | F3: Yes | No | G3: Screener — Myntra user | H3: If No → Thanks
A4: S2 | B4: 1. Screener | C4: mcq | D4: TRUE | E4: How do you describe yourself? | F4: Woman | Man | Non-binary | Prefer not to say | G4: Segment — gender
A5: S3 | B5: 1. Screener | C5: mcq | D5: TRUE | E5: Your age | F5: Under 24 | 24–32 | 33–40 | 41+ | G5: Segment — age
A6: S4 | B6: 1. Screener | C6: dropdown | D6: TRUE | E6: Where do you live? | F6: Bengaluru | Hyderabad | Delhi | Gurugram | Noida | Coimbatore | Mumbai | Pune | Non-metro India | G6: Segment — city
A7: S5 | B7: 1. Screener | C7: mcq | D7: TRUE | E7: About how many items are in your Myntra wishlist right now? | F7: 0 | 1–14 | 15–40 | 41–80 | 81+ | G7: Wishlist depth | H7: If 0 → Thanks
A8: S6 | B8: 1. Screener | C8: mcq | D8: TRUE | E8: In the last 60 days, did you save something on Myntra and not buy it? | F8: Yes | No | G8: Recent stall
A9: S7 | B9: 1. Screener | C9: mcq | D9: TRUE | E9: How often do you open Myntra? | F9: Most days | About weekly | A few times a month | Rarely | G9: Usage
A10: Q1 | B10: 2. The last unsold save | C10: mcq | D10: TRUE | E10: Think of the last item you hearted and still have not bought. Why did you save it that day? | F10: I meant to buy it soon | To compare with other pieces I saved | For an occasion / event coming up | Waiting for a sale or price drop | I just liked it — not sure I’ll buy | Other | G10: Part 3 — why they saved
A11: Q2 | B11: 2. The last unsold save | C11: mcq | D11: TRUE | E11: Do you still intend to buy that item in the next 30 days? | F11: Yes | Maybe | No | G11: Part 3 — still intend
A12: Q3 | B12: 2. The last unsold save | C12: mcq | D12: TRUE | E12: What is the MAIN thing stopping you from buying it? | F12: I don’t know if it will fit me / this brand’s cut | I’m worried about returns exchange-only or a seal tag | I don’t trust the size chart | I can’t choose between a few similar things I saved | I’m not sure the fabric / quality matches the photo | I’m not sure when or where I’d wear it | I’m waiting for a sale or discount | My wishlist is a mess — I forget it | I was never really going to buy it | G12: WhyWait primary barrier
A13: Q4 | B13: 2. The last unsold save | C13: multi | D13: TRUE | E13: After you already liked the photo what were you still unsure about? | F13: Fit on my body / height | Which size to pick | Whether I can return or exchange it | Whether the next size exists | Occasion / office-appropriateness | Quality vs photo | Price | Nothing — I was just bookmarking | G13: Uncertainties after identification
A14: Q5 | B14: 2. The last unsold save | C14: multi | D14: TRUE | E14: What would make you buy it this week? | F14: A kept-vs-returned story from people my size and height on the wishlist card | Return / seal-tag / exchange-only written as a sentence on the card | A suggested size that stays with the saved item | A side-by-side of the other pieces I saved on fit — not on discount % | A coupon or sale | A friend telling me to buy it | Nothing — I don’t intend to buy it | G14: What would make them purchase
A15: Q6 | B15: 2. The last unsold save | C15: multi | D15: TRUE | E15: What information do you still need that the wishlist does not give you today? | F15: How this sat on someone near my height | Whether people who wear my usual size kept it | Return policy in words not an icon | Ethnic size vs my top size labelled separately | Length / crop / rise for my height | Whether Try and Buy exists on this SKU | I have everything I need | G15: Info still needed
A16: Q7 | B16: 2. The last unsold save | C16: mcq | D16: TRUE | E16: Are you comparing this with other items you already saved? | F16: Yes — I will buy one of them | Yes — but I may buy none | No | G16: Alternatives
A17: Q8 | B17: 3. Outside the app | C17: multi | D17: TRUE | E17: Before you decide what do you do outside Myntra? | F17: WhatsApp / send photos to friends or family | YouTube haul / try-on | Instagram | Google size charts or reviews | Visit a store to touch fabric or try a similar cut | Order two sizes and return one (or used to) | Nothing — I decide in the app | I just wait and never decide | G17: Outside the app
A18: Q9 | B18: 3. Outside the app | C18: multi | D18: TRUE | E18: How do you reduce the risk of a wrong size today? | F18: Only buy brands I have kept before | Read 50+ reviews on the product page | Ask a friend their size in that brand | Order two sizes | Wait for a sale so a failed return hurts less | Don’t buy — leave it wishlisted | G18: How they cope
A19: Q10a | B19: 3. Outside the app | C19: mcq | D19: TRUE | E19: Have you ever got a size explanation on the product page then opened the same item from wishlist later and found only the photo left? | F19: Yes | No | Not sure | G19: PDP advice does not travel
... A30: Q13 | B30: 6. One sentence | C30: long | D30: FALSE | E30: In one or two sentences: why is that saved item still not purchased? | F30: (verbatim) | G30: Open freeze

Sheet Codebook
A1: field | B1: in_target_logic | C1: q3_code | D1: notes
A2: S2 | B2: Must be Woman for target | D2: Keep all genders in the full file. Target cut is women only.
A3: S3 | B3: Must be 24–32 | D3: Under 24 and 33+ are the segment-diff rows.
A4: S4 | B4: Bengaluru / Hyderabad / Delhi / Gurugram / Noida / Coimbatore | D4: Mumbai / Pune / non-metro are the segment-diff rows.
A5: S5 | B5: 15–40 or 41–80 or 81+ | D5: 1–14 is too shallow vs interview screener.
A6: S6 | B6: Yes | D6: Recent stall.
A7: S7 | B7: Most days or About weekly
A8: Q3 | C8: fit="I don’t know if it will fit me / this brand’s cut"; return="I’m worried about returns"; chart="I don’t trust the size chart"; compare="I can’t choose between"; quality="fabric / quality"; occasion="when or where I’d wear it"; sale="waiting for a sale"; clutter="wishlist is a mess"; bookmark="never really going to buy it" | D8: Forced primary. Sale stays DISQUALIFIED even if it wins frequency.
A9: Q5 | C9: legal_fit = kept-vs-returned story; legal_policy = return in words; legal_persist = suggested size stays; legal_compare = side-by-side on fit; illegal = coupon; social = friend; none = don’t intend | D9: Compare legal vs illegal levers inside the same person.
A10: Q8 | C10: off_app = any of WhatsApp YouTube Instagram Google store two-sizes wait | D10: Nothing = decided in-app.
A11: Q10a | C11: mechanism_yes = Yes | D11: Supports Verdict on the saved card.
A12: Q12 | C12: intent / mix / bookmark | D12: Bookmark → Still exploring. Do not convert.

Sheet Responses
A1: Timestamp | B1: C1 | C1: S1 | D1: S2 | E1: S3 | F1: S4 | G1: S5 | H1: S6 | I1: S7 | J1: Q1 | K1: Q2 | L1: Q3 | M1: Q4 | N1: Q5 | O1: Q6 | P1: Q7 | Q1: Q8 | R1: Q9 | S1: Q10a | T1: Q11_fit | U1: Q11_return | V1: Q11_price | W1: Q11_occasion | X1: Q11_social | Y1: Q12 | Z1: D1 | AA1: D2 | AB1: D3 | AC1: D4 | AD1: Q13 | AE1: in_target | AF1: q3_code | AG1: off_app | AH1: legal_lever
A2: 8/9/2026 14:08:06 | B2: Yes, continue | C2: Yes | D2: Woman | E2: 24–32 | F2: Gurugram | G2: 15–40 | H2: Yes | I2: About weekly | J2: I meant to buy it soon | K2: Maybe | L2: I don’t trust the size chart | M2: Which size to pick, Fit on my body / height | N2: A kept-vs-returned story from people my size and height, on the wishlist card, A suggested size that stays with the saved item (not only on the product page), Return / seal-tag / exchange-only written as a sentence on the card, A friend telling me to buy it | O2: How this sat on someone near my height, Whether people who wear my usual size kept it, Length / crop / rise for my height | P2: No | Q2: WhatsApp / send photos to friends or family, YouTube haul / try-on, Instagram | R2: Only buy brands I have kept before, Read 50+ reviews on the product page | S2: Yes | T2: 5 | U2: 3 | V2: 2 | W2: 2 | X2: 4 | Y2: A mix | Z2: 5'2"–5'5" | AA2: M | AB2: No — ethnic runs different | AC2: Mostly workwear | AD2: Theatre. People like me, not centimetres. | AE2: =IF(C2="","",IF(AND(D2="Woman",E2="24–32",OR(F2="Bengaluru",F2="Hyderabad",F2="Delhi",F2="Gurugram",F2="Noida",F2="Coimbatore"),OR(G2="15–40",G2="41–80",G2="81+"),H2="Yes",OR(I2="Most days",I2="About weekly")),"YES","NO")) | AF2: =IF(L2="","",IF(ISNUMBER(SEARCH("fit",L2)),"fit",IF(ISNUMBER(SEARCH("return",L2))+ISNUMBER(SEARCH("seal",L2)),"return",IF(ISNUMBER(SEARCH("chart",L2)),"chart",IF(ISNUMBER(SEARCH("choose",L2)),"compare",IF(ISNUMBER(SEARCH("sale",L2)),"sale",IF(ISNUMBER(SEARCH("never",L2)),"bookmark",IF(ISNUMBER(SEARCH("mess",L2)),"clutter",IF(ISNUMBER(SEARCH("wear it",L2)),"occasion",IF(ISNUMBER(SEARCH("quality",L2)),"quality","other")))))))))) | AG2: =IF(Q2="","",IF(OR(ISNUMBER(SEARCH("WhatsApp",Q2)),ISNUMBER(SEARCH("YouTube",Q2)),ISNUMBER(SEARCH("Instagram",Q2)),ISNUMBER(SEARCH("Google",Q2)),ISNUMBER(SEARCH("store",Q2)),ISNUMBER(SEARCH("two sizes",Q2))),"off_app","in_app")) | AH2: =IF(N2="","",IF(ISNUMBER(SEARCH("coupon",N2))+ISNUMBER(SEARCH("sale",N2))+ISNUMBER(SEARCH("kept-vs-returned",N2))+ISNUMBER(SEARCH("sentence",N2))+ISNUMBER(SEARCH("stays with",N2))+ISNUMBER(SEARCH("side-by-side",N2)),IF(ISNUMBER(SEARCH("kept-vs-returned",N2))+ISNUMBER(SEARCH("sentence",N2))+ISNUMBER(SEARCH("stays with",N2))+ISNUMBER(SEARCH("side-by-side",N2)),"legal_present",IF(ISNUMBER(SEARCH("coupon",N2))+ISNUMBER(SEARCH("sale",N2)),"coupon_only","other")),"other"))
A3: 8/10/2026 5:36:42 | B3: Yes, continue | C3: Yes | D3: Woman | E3: 24–32 | F3: Noida | G3: 15–40 | H3: Yes | I3: About weekly | J3: I meant to buy it soon | K3: Yes | L3: I don’t know if it will fit me / this brand’s cut | M3: Fit on my body / height, Which size to pick | N3: A kept-vs-returned story from people my size and height, on the wishlist card, A suggested size that stays with the saved item (not only on the product page) | O3: How this sat on someone near my height, Whether people who wear my usual size kept it, Length / crop / rise for my height, Ethnic size vs my top size, labelled separately | P3: No | Q3: WhatsApp / send photos to friends or family, YouTube haul / try-on, Visit a store to touch fabric or try a similar cut | R3: Only buy brands I have kept before, Read 50+ reviews on the product page, Ask a friend their size in that brand | S3: Yes | T3: 5 | U3: 3 | V3: 2 | W3: 2 | X3: 2 | Y3: A shopping list I intend to buy from | Z3: 5'2"–5'5" | AA3: M | AB3: No — ethnic runs different | AC3: Mostly workwear | AE3: =IF(C3="","",IF(AND(D3="Woman",E3="24–32",OR(F3="Bengaluru",F3="Hyderabad",F3="Delhi",F3="Gurugram",F3="Noida",F3="Coimbatore"),OR(G3="15–40",G3="41–80",G3="81+"),H3="Yes",OR(I3="Most days",I3="About weekly")),"YES","NO")) | AF3: =IF(L3="","",IF(ISNUMBER(SEARCH("fit",L3)),"fit",IF(ISNUMBER(SEARCH("return",L3))+ISNUMBER(SEARCH("seal",L3)),"return",IF(ISNUMBER(SEARCH("chart",L3)),"chart",IF(ISNUMBER(SEARCH("choose",L3)),"compare",IF(ISNUMBER(SEARCH("sale",L3)),"sale",IF(ISNUMBER(SEARCH("never",L3)),"bookmark",IF(ISNUMBER(SEARCH("mess",L3)),"clutter",IF(ISNUMBER(SEARCH("wear it",L3)),"occasion",IF(ISNUMBER(SEARCH("quality",L3)),"quality","other")))))))))) | AG3: =IF(Q3="","",IF(OR(ISNUMBER(SEARCH("WhatsApp",Q3)),ISNUMBER(SEARCH("YouTube",Q3)),ISNUMBER(SEARCH("Instagram",Q3)),ISNUMBER(SEARCH("Google",Q3)),ISNUMBER(SEARCH("store",Q3)),ISNUMBER(SEARCH("two sizes",Q3))),"off_app","in_app")) | AH3: =IF(N3="","",IF(ISNUMBER(SEARCH("coupon",N3))+ISNUMBER(SEARCH("sale",N3))+ISNUMBER(SEARCH("kept-vs-returned",N3))+ISNUMBER(SEARCH("sentence",N3))+ISNUMBER(SEARCH("stays with",N3))+ISNUMBER(SEARCH("side-by-side",N3)),IF(ISNUMBER(SEARCH("kept-vs-returned",N3))+ISNUMBER(SEARCH("sentence",N3))+ISNUMBER(SEARCH("stays with",N3))+ISNUMBER(SEARCH("side-by-side",N3)),"legal_present",IF(ISNUMBER(SEARCH("coupon",N3))+ISNUMBER(SEARCH("sale",N3)),"coupon_only","other")),"other"))
A4: 8/10/2026 9:55:17 | B4: Yes, continue | C4: Yes | D4: Woman | E4: 24–32 | F4: Non-metro India | G4: 41–80 | H4: Yes | I4: Rarely | J4: I just liked it — not sure I’ll buy | K4: No | L4: My wishlist is a mess — I forget it | M4: Nothing — I was just bookmarking | N4: Nothing — I don’t intend to buy it | O4: How this sat on someone near my height, Return policy in words, not an icon | P4: No | Q4: WhatsApp / send photos to friends or family, YouTube haul / try-on, Instagram | R4: Only buy brands I have kept before, Read 50+ reviews on the product page, Don’t buy — leave it wishlisted | S4: Yes | T4: 3 | U4: 3 | V4: 2 | W4: 2 | X4: 4 | Y4: A mix | Z4: Under 5'2" | AA4: M | AB4: Yes, same letter | AC4: Mix of workwear and occasion | AD4: 96 items. I lose the one I actually meant to buy. | AE4: =IF(C4="","",IF(AND(D4="Woman",E4="24–32",OR(F4="Bengaluru",F4="Hyderabad",F4="Delhi",F4="Gurugram",F4="Noida",F4="Coimbatore"),OR(G4="15–40",G4="41–80",G4="81+"),H4="Yes",OR(I4="Most days",I4="About weekly")),"YES","NO")) | AF4: =IF(L4="","",IF(ISNUMBER(SEARCH("fit",L4)),"fit",IF(ISNUMBER(SEARCH("return",L4))+ISNUMBER(SEARCH("seal",L4)),"return",IF(ISNUMBER(SEARCH("chart",L4)),"chart",IF(ISNUMBER(SEARCH("choose",L4)),"compare",IF(ISNUMBER(SEARCH("sale",L4)),"sale",IF(ISNUMBER(SEARCH("never",L4)),"bookmark",IF(ISNUMBER(SEARCH("mess",L4)),"clutter",IF(ISNUMBER(SEARCH("wear it",L4)),"occasion",IF(ISNUMBER(SEARCH("quality",L4)),"quality","other")))))))))) | AG4: =IF(Q4="","",IF(OR(ISNUMBER(SEARCH("WhatsApp",Q4)),ISNUMBER(SEARCH("YouTube",Q4)),ISNUMBER(SEARCH("Instagram",Q4)),ISNUMBER(SEARCH("Google",Q4)),ISNUMBER(SEARCH("store",Q4)),ISNUMBER(SEARCH("two sizes",Q4))),"off_app","in_app")) | AH4: =IF(N4="","",IF(ISNUMBER(SEARCH("coupon",N4))+ISNUMBER(SEARCH("sale",N4))+ISNUMBER(SEARCH("kept-vs-returned",N4))+ISNUMBER(SEARCH("sentence",N4))+ISNUMBER(SEARCH("stays with",N4))+ISNUMBER(SEARCH("side-by-side",N4)),IF(ISNUMBER(SEARCH("kept-vs-returned",N4))+ISNUMBER(SEARCH("sentence",N4))+ISNUMBER(SEARCH("stays with",N4))+ISNUMBER(SEARCH("side-by-side",N4)),"legal_present",IF(ISNUMBER(SEARCH("coupon",N4))+ISNUMBER(SEARCH("sale",N4)),"coupon_only","other")),"other"))
A5: 8/10/2026 10:42:47 | B5: Yes, continue | C5: Yes | D5: Woman | E5: 33–40 | F5: Bengaluru | G5: 15–40 | H5: Yes | I5: About weekly | J5: For an occasion / event coming up | K5: Maybe | L5: I’m not sure when or where I’d wear it | M5: Occasion / office-appropriateness | N5: A kept-vs-returned story from people my size and height, on the wishlist card, A suggested size that stays with the saved item (not only on the product page) | O5: How this sat on someone near my height, Return policy in words, not an icon | P5: No | Q5: WhatsApp / send photos to friends or family, YouTube haul / try-on, Google size charts or reviews | R5: Only buy brands I have kept before, Read 50+ reviews on the product page, Ask a friend their size in that brand | S5: Yes | T5: 3 | U5: 3 | V5: 2 | W5: 5 | X5: 2 | Y5: A mix | Z5: 5'2"–5'5" | AA5: XS | AB5: I don’t buy ethnic on Myntra | AC5: Mostly occasion / ethnic | AD5: Function is in three weeks. Dupatta length and seal tag — that’s the stall. | AE5: =IF(C5="","",IF(AND(D5="Woman",E5="24–32",OR(F5="Bengaluru",F5="Hyderabad",F5="Delhi",F5="Gurugram",F5="Noida",F5="Coimbatore"),OR(G5="15–40",G5="41–80",G5="81+"),H5="Yes",OR(I5="Most days",I5="About weekly")),"YES","NO")) | AF5: =IF(L5="","",IF(ISNUMBER(SEARCH("fit",L5)),"fit",IF(ISNUMBER(SEARCH("return",L5))+ISNUMBER(SEARCH("seal",L5)),"return",IF(ISNUMBER(SEARCH("chart",L5)),"chart",IF(ISNUMBER(SEARCH("choose",L5)),"compare",IF(ISNUMBER(SEARCH("sale",L5)),"sale",IF(ISNUMBER(SEARCH("never",L5)),"bookmark",IF(ISNUMBER(SEARCH("mess",L5)),"clutter",IF(ISNUMBER(SEARCH("wear it",L5)),"occasion",IF(ISNUMBER(SEARCH("quality",L5)),"quality","other")))))))))) | AG5: =IF(Q5="","",IF(OR(ISNUMBER(SEARCH("WhatsApp",Q5)),ISNUMBER(SEARCH("YouTube",Q5)),ISNUMBER(SEARCH("Instagram",Q5)),ISNUMBER(SEARCH("Google",Q5)),ISNUMBER(SEARCH("store",Q5)),ISNUMBER(SEARCH("two sizes",Q5))),"off_app","in_app")) | AH5: =IF(N5="","",IF(ISNUMBER(SEARCH("coupon",N5))+ISNUMBER(SEARCH("sale",N5))+ISNUMBER(SEARCH("kept-vs-returned",N5))+ISNUMBER(SEARCH("sentence",N5))+ISNUMBER(SEARCH("stays with",N5))+ISNUMBER(SEARCH("side-by-side",N5)),IF(ISNUMBER(SEARCH("kept-vs-returned",N5))+ISNUMBER(SEARCH("sentence",N5))+ISNUMBER(SEARCH("stays with",N5))+ISNUMBER(SEARCH("side-by-side",N5)),"legal_present",IF(ISNUMBER(SEARCH("coupon",N5))+ISNUMBER(SEARCH("sale",N5)),"coupon_only","other")),"other"))
A6: 8/10/2026 14:01:58 | B6: Yes, continue | C6: Yes | D6: Woman | E6: 24–32 | F6: Noida | G6: 15–40 | H6: Yes | I6: About weekly | J6: I meant to buy it soon | K6: Yes | L6: I don’t know if it will fit me / this brand’s cut | M6: Fit on my body / height, Which size to pick | N6: A kept-vs-returned story from people my size and height, on the wishlist card, A suggested size that stays with the saved item (not only on the product page), Return / seal-tag / exchange-only written as a sentence on the card | O6: How this sat on someone near my height, Whether people who wear my usual size kept it, Length / crop / rise for my height | P6: No | Q6: WhatsApp / send photos to friends or family, YouTube haul / try-on, Visit a store to touch fabric or try a similar cut | R6: Only buy brands I have kept before, Read 50+ reviews on the product page, Don’t buy — leave it wishlisted | S6: Yes | T6: 5 | U6: 3 | V6: 2 | W6: 2 | X6: 2 | Y6: A shopping list I intend to buy from | Z6: 5'2"–5'5" | AA6: M | AB6: Yes, same letter | AC6: Mix of workwear and occasion | AD6: Straight kurta for work. Need to know if it hits below the knee on me. | AE6: =IF(C6="","",IF(AND(D6="Woman",E6="24–32",OR(F6="Bengaluru",F6="Hyderabad",F6="Delhi",F6="Gurugram",F6="Noida",F6="Coimbatore"),OR(G6="15–40",G6="41–80",G6="81+"),H6="Yes",OR(I6="Most days",I6="About weekly")),"YES","NO")) | AF6: =IF(L6="","",IF(ISNUMBER(SEARCH("fit",L6)),"fit",IF(ISNUMBER(SEARCH("return",L6))+ISNUMBER(SEARCH("seal",L6)),"return",IF(ISNUMBER(SEARCH("chart",L6)),"chart",IF(ISNUMBER(SEARCH("choose",L6)),"compare",IF(ISNUMBER(SEARCH("sale",L6)),"sale",IF(ISNUMBER(SEARCH("never",L6)),"bookmark",IF(ISNUMBER(SEARCH("mess",L6)),"clutter",IF(ISNUMBER(SEARCH("wear it",L6)),"occasion",IF(ISNUMBER(SEARCH("quality",L6)),"quality","other")))))))))) | AG6: =IF(Q6="","",IF(OR(ISNUMBER(SEARCH("WhatsApp",Q6)),ISNUMBER(SEARCH("YouTube",Q6)),ISNUMBER(SEARCH("Instagram",Q6)),ISNUMBER(SEARCH("Google",Q6)),ISNUMBER(SEARCH("store",Q6)),ISNUMBER(SEARCH("two sizes",Q6))),"off_app","in_app")) | AH6: =IF(N6="","",IF(ISNUMBER(SEARCH("coupon",N6))+ISNUMBER(SEARCH("sale",N6))+ISNUMBER(SEARCH("kept-vs-returned",N6))+ISNUMBER(SEARCH("sentence",N6))+ISNUMBER(SEARCH("stays with",N6))+ISNUMBER(SEARCH("side-by-side",N6)),IF(ISNUMBER(SEARCH("kept-vs-returned",N6))+ISNUMBER(SEARCH("sentence",N6))+ISNUMBER(SEARCH("stays with",N6))+ISNUMBER(SEARCH("side-by-side",N6)),"legal_present",IF(ISNUMBER(SEARCH("coupon",N6))+ISNUMBER(SEARCH("sale",N6)),"coupon_only","other")),"other"))
A7: 8/10/2026 16:50:09 | B7: Yes, continue | C7: Yes | D7: Woman | E7: 24–32 | F7: Delhi | G7: 41–80 | H7: Yes | I7: About weekly | J7: I just liked it — not sure I’ll buy | K7: No | L7: I was never really going to buy it | M7: Nothing — I was just bookmarking | N7: Nothing — I don’t intend to buy it | O7: I have everything I need | P7: No | Q7: YouTube haul / try-on | R7: Don’t buy — leave it wishlisted | S7: No | T7: 2 | U7: 2 | V7: 2 | W7: 2 | X7: 3 | Y7: A moodboard / Pinterest | Z7: 5'2"–5'5" | AA7: XS | AB7: Yes, same letter | AC7: Mostly workwear | AE7: =IF(C7="","",IF(AND(D7="Woman",E7="24–32",OR(F7="Bengaluru",F7="Hyderabad",F7="Delhi",F7="Gurugram",F7="Noida",F7="Coimbatore"),OR(G7="15–40",G7="41–80",G7="81+"),H7="Yes",OR(I7="Most days",I7="About weekly")),"YES","NO")) | AF7: =IF(L7="","",IF(ISNUMBER(SEARCH("fit",L7)),"fit",IF(ISNUMBER(SEARCH("return",L7))+ISNUMBER(SEARCH("seal",L7)),"return",IF(ISNUMBER(SEARCH("chart",L7)),"chart",IF(ISNUMBER(SEARCH("choose",L7)),"compare",IF(ISNUMBER(SEARCH("sale",L7)),"sale",IF(ISNUMBER(SEARCH("never",L7)),"bookmark",IF(ISNUMBER(SEARCH("mess",L7)),"clutter",IF(ISNUMBER(SEARCH("wear it",L7)),"occasion",IF(ISNUMBER(SEARCH("quality",L7)),"quality","other")))))))))) | AG7: =IF(Q7="","",IF(OR(ISNUMBER(SEARCH("WhatsApp",Q7)),ISNUMBER(SEARCH("YouTube",Q7)),ISNUMBER(SEARCH("Instagram",Q7)),ISNUMBER(SEARCH("Google",Q7)),ISNUMBER(SEARCH("store",Q7)),ISNUMBER(SEARCH("two sizes",Q7))),"off_app","in_app")) | AH7: =IF(N7="","",IF(ISNUMBER(SEARCH("coupon",N7))+ISNUMBER(SEARCH("sale",N7))+ISNUMBER(SEARCH("kept-vs-returned",N7))+ISNUMBER(SEARCH("sentence",N7))+ISNUMBER(SEARCH("stays with",N7))+ISNUMBER(SEARCH("side-by-side",N7)),IF(ISNUMBER(SEARCH("kept-vs-returned",N7))+ISNUMBER(SEARCH("sentence",N7))+ISNUMBER(SEARCH("stays with",N7))+ISNUMBER(SEARCH("side-by-side",N7)),"legal_present",IF(ISNUMBER(SEARCH("coupon",N7))+ISNUMBER(SEARCH("sale",N7)),"coupon_only","other")),"other"))
A8: 8/10/2026 18:52:02 | B8: Yes, continue | C8: Yes | D8: Woman | E8: 24–32 | F8: Gurugram | G8: 15–40 | H8: Yes | I8: About weekly | J8: I meant to buy it soon | K8: Yes | L8: I don’t know if it will fit me / this brand’s cut | M8: Fit on my body / height, Which size to pick | N8: A kept-vs-returned story from people my size and height, on the wishlist card, A suggested size that stays with the saved item (not only on the product page) | O8: How this sat on someone near my height, Whether people who wear my usual size kept it, Length / crop / rise for my height | P8: No | Q8: WhatsApp / send photos to friends or family, YouTube haul / try-on, Visit a store to touch fabric or try a similar cut | R8: Only buy brands I have kept before, Read 50+ reviews on the product page, Ask a friend their size in that brand, Don’t buy — leave it wishlisted | S8: Yes | T8: 5 | U8: 3 | V8: 2 | W8: 2 | X8: 2 | Y8: A shopping list I intend to buy from | Z8: 5'2"–5'5" | AA8: S | AB8: Yes, same letter | AC8: Mix of workwear and occasion | AD8: The size advice was on the product page. Wishlist is just a photo. I start over every time. | AE8: =IF(C8="","",IF(AND(D8="Woman",E8="24–32",OR(F8="Bengaluru",F8="Hyderabad",F8="Delhi",F8="Gurugram",F8="Noida",F8="Coimbatore"),OR(G8="15–40",G8="41–80",G8="81+"),H8="Yes",OR(I8="Most days",I8="About weekly")),"YES","NO")) | AF8: =IF(L8="","",IF(ISNUMBER(SEARCH("fit",L8)),"fit",IF(ISNUMBER(SEARCH("return",L8))+ISNUMBER(SEARCH("seal",L8)),"return",IF(ISNUMBER(SEARCH("chart",L8)),"chart",IF(ISNUMBER(SEARCH("choose",L8)),"compare",IF(ISNUMBER(SEARCH("sale",L8)),"sale",IF(ISNUMBER(SEARCH("never",L8)),"bookmark",IF(ISNUMBER(SEARCH("mess",L8)),"clutter",IF(ISNUMBER(SEARCH("wear it",L8)),"occasion",IF(ISNUMBER(SEARCH("quality",L8)),"quality","other")))))))))) | AG8: =IF(Q8="","",IF(OR(ISNUMBER(SEARCH("WhatsApp",Q8)),ISNUMBER(SEARCH("YouTube",Q8)),ISNUMBER(SEARCH("Instagram",Q8)),ISNUMBER(SEARCH("Google",Q8)),ISNUMBER(SEARCH("store",Q8)),ISNUMBER(SEARCH("two sizes",Q8))),"off_app","in_app")) | AH8: =IF(N8="","",IF(ISNUMBER(SEARCH("coupon",N8))+ISNUMBER(SEARCH("sale",N8))+ISNUMBER(SEARCH("kept-vs-returned",N8))+ISNUMBER(SEARCH("sentence",N8))+ISNUMBER(SEARCH("stays with",N8))+ISNUMBER(SEARCH("side-by-side",N8)),IF(ISNUMBER(SEARCH("kept-vs-returned",N8))+ISNUMBER(SEARCH("sentence",N8))+ISNUMBER(SEARCH("stays with",N8))+ISNUMBER(SEARCH("side-by-side",N8)),"legal_present",IF(ISNUMBER(SEARCH("coupon",N8))+ISNUMBER(SEARCH("sale",N8)),"coupon_only","other")),"other"))
A9: 8/10/2026 22:20:28 | B9: Yes, continue | C9: Yes | D9: Woman | E9: 24–32 | F9: Gurugram | G9: 15–40 | H9: Yes | I9: Most days | J9: Waiting for a sale or price drop | K9: Yes | L9: I’m waiting for a sale or discount | M9: Price, Whether I can return or exchange it | N9: A coupon or sale, A kept-vs-returned story from people my size and height, on the wishlist card, A suggested size that stays with the saved item (not only on the product page) | O9: How this sat on someone near my height, Return policy in words, not an icon | P9: No | Q9: WhatsApp / send photos to friends or family, YouTube haul / try-on, Instagram | R9: Only buy brands I have kept before, Read 50+ reviews on the product page, Wait for a sale so a failed return hurts less, Don’t buy — leave it wishlisted | S9: Yes | T9: 3 | U9: 4 | V9: 5 | W9: 2 | X9: 2 | Y9: A shopping list I intend to buy from | Z9: 5'5"–5'8" | AA9: L | AB9: No — ethnic runs different | AC9: Mostly workwear | AD9: Salary week I browse. I still don’t bag if fit is a coin flip, even on sale. | AE9: =IF(C9="","",IF(AND(D9="Woman",E9="24–32",OR(F9="Bengaluru",F9="Hyderabad",F9="Delhi",F9="Gurugram",F9="Noida",F9="Coimbatore"),OR(G9="15–40",G9="41–80",G9="81+"),H9="Yes",OR(I9="Most days",I9="About weekly")),"YES","NO")) | AF9: =IF(L9="","",IF(ISNUMBER(SEARCH("fit",L9)),"fit",IF(ISNUMBER(SEARCH("return",L9))+ISNUMBER(SEARCH("seal",L9)),"return",IF(ISNUMBER(SEARCH("chart",L9)),"chart",IF(ISNUMBER(SEARCH("choose",L9)),"compare",IF(ISNUMBER(SEARCH("sale",L9)),"sale",IF(ISNUMBER(SEARCH("never",L9)),"bookmark",IF(ISNUMBER(SEARCH("mess",L9)),"clutter",IF(ISNUMBER(SEARCH("wear it",L9)),"occasion",IF(ISNUMBER(SEARCH("quality",L9)),"quality","other")))))))))) | AG9: =IF(Q9="","",IF(OR(ISNUMBER(SEARCH("WhatsApp",Q9)),ISNUMBER(SEARCH("YouTube",Q9)),ISNUMBER(SEARCH("Instagram",Q9)),ISNUMBER(SEARCH("Google",Q9)),ISNUMBER(SEARCH("store",Q9)),ISNUMBER(SEARCH("two sizes",Q9))),"off_app","in_app")) | AH9: =IF(N9="","",IF(ISNUMBER(SEARCH("coupon",N9))+ISNUMBER(SEARCH("sale",N9))+ISNUMBER(SEARCH("kept-vs-returned",N9))+ISNUMBER(SEARCH("sentence",N9))+ISNUMBER(SEARCH("stays with",N9))+ISNUMBER(SEARCH("side-by-side",N9)),IF(ISNUMBER(SEARCH("kept-vs-returned",N9))+ISNUMBER(SEARCH("sentence",N9))+ISNUMBER(SEARCH("stays with",N9))+ISNUMBER(SEARCH("side-by-side",N9)),"legal_present",IF(ISNUMBER(SEARCH("coupon",N9))+ISNUMBER(SEARCH("sale",N9)),"coupon_only","other")),"other"))
A10: 8/11/2026 3:52:18 | B10: Yes, continue | C10: Yes | D10: Woman | E10: 24–32 | F10: Bengaluru | G10: 15–40 | H10: Yes | I10: Most days | J10: Waiting for a sale or price drop | K10: Yes | L10: I’m waiting for a sale or discount | M10: Price, Whether I can return or exchange it | N10: A coupon or sale, Return / seal-tag / exchange-only written as a sentence on the card, A kept-vs-returned story from people my size and height, on the wishlist card | O10: How this sat on someone near my height, Return policy in words, not an icon | P10: Yes — but I may buy none | Q10: WhatsApp / send photos to friends or family, YouTube haul / try-on, Instagram | R10: Only buy brands I have kept before, Read 50+ reviews on the product page, Wait for a sale so a failed return hurts less, Don’t buy — leave it wishlisted | S10: Yes | T10: 3 | U10: 4 | V10: 5 | W10: 2 | X10: 2 | Y10: A shopping list I intend to buy from | Z10: 5'5"–5'8" | AA10: S | AB10: Yes, same letter | AC10: Mix of workwear and occasion | AE10: =IF(C10="","",IF(AND(D10="Woman",E10="24–32",OR(F10="Bengaluru",F10="Hyderabad",F10="Delhi",F10="Gurugram",F10="Noida",F10="Coimbatore"),OR(G10="15–40",G10="41–80",G10="81+"),H10="Yes",OR(I10="Most days",I10="About weekly")),"YES","NO")) | AF10: =IF(L10="","",IF(ISNUMBER(SEARCH("fit",L10)),"fit",IF(ISNUMBER(SEARCH("return",L10))+ISNUMBER(SEARCH("seal",L10)),"return",IF(ISNUMBER(SEARCH("chart",L10)),"chart",IF(ISNUMBER(SEARCH("choose",L10)),"compare",IF(ISNUMBER(SEARCH("sale",L10)),"sale",IF(ISNUMBER(SEARCH("never",L10)),"bookmark",IF(ISNUMBER(SEARCH("mess",L10)),"clutter",IF(ISNUMBER(SEARCH("wear it",L10)),"occasion",IF(ISNUMBER(SEARCH("quality",L10)),"quality","other")))))))))) | AG10: =IF(Q10="","",IF(OR(ISNUMBER(SEARCH("WhatsApp",Q10)),ISNUMBER(SEARCH("YouTube",Q10)),ISNUMBER(SEARCH("Instagram",Q10)),ISNUMBER(SEARCH("Google",Q10)),ISNUMBER(SEARCH("store",Q10)),ISNUMBER(SEARCH("two sizes",Q10))),"off_app","in_app")) | AH10: =IF(N10="","",IF(ISNUMBER(SEARCH("coupon",N10))+ISNUMBER(SEARCH("sale",N10))+ISNUMBER(SEARCH("kept-vs-returned",N10))+ISNUMBER(SEARCH("sentence",N10))+ISNUMBER(SEARCH("stays with",N10))+ISNUMBER(SEARCH("side-by-side",N10)),IF(ISNUMBER(SEARCH("kept-vs-returned",N10))+ISNUMBER(SEARCH("sentence",N10))+ISNUMBER(SEARCH("stays with",N10))+ISNUMBER(SEARCH("side-by-side",N10)),"legal_present",IF(ISNUMBER(SEARCH("coupon",N10))+ISNUMBER(SEARCH("sale",N10)),"coupon_only","other")),"other"))
A11: 8/11/2026 8:59:04 | B11: Yes, continue | C11: Yes | D11: Woman | E11: Under 24 | F11: Pune | G11: 1–14 | H11: Yes | I11: Most days | J11: Waiting for a sale or price drop | K11: Yes | L11: I’m waiting for a sale or discount | M11: Price, Whether I can return or exchange it | N11: A coupon or sale, Return / seal-tag / exchange-only written as a sentence on the card, A kept-vs-returned story from people my size and height, on the wishlist card | O11: How this sat on someone near my height, Return policy in words, not an icon | P11: Yes — but I may buy none | Q11: WhatsApp / send photos to friends or family, YouTube haul / try-on, Google size charts or reviews | R11: Only buy brands I have kept before, Read 50+ reviews on the product page, Wait for a sale so a failed return hurts less | S11: No | T11: 3 | U11: 4 | V11: 5 | W11: 2 | X11: 2 | Y11: A shopping list I intend to buy from | Z11: 5'5"–5'8" | AA11: XS | AB11: No — ethnic runs different | AC11: Mix of workwear and occasion | AE11: =IF(C11="","",IF(AND(D11="Woman",E11="24–32",OR(F11="Bengaluru",F11="Hyderabad",F11="Delhi",F11="Gurugram",F11="Noida",F11="Coimbatore"),OR(G11="15–40",G11="41–80",G11="81+"),H11="Yes",OR(I11="Most days",I11="About weekly")),"YES","NO")) | AF11: =IF(L11="","",IF(ISNUMBER(SEARCH("fit",L11)),"fit",IF(ISNUMBER(SEARCH("return",L11))+ISNUMBER(SEARCH("seal",L11)),"return",IF(ISNUMBER(SEARCH("chart",L11)),"chart",IF(ISNUMBER(SEARCH("choose",L11)),"compare",IF(ISNUMBER(SEARCH("sale",L11)),"sale",IF(ISNUMBER(SEARCH("never",L11)),"bookmark",IF(ISNUMBER(SEARCH("mess",L11)),"clutter",IF(ISNUMBER(SEARCH("wear it",L11)),"occasion",IF(ISNUMBER(SEARCH("quality",L11)),"quality","other")))))))))) | AG11: =IF(Q11="","",IF(OR(ISNUMBER(SEARCH("WhatsApp",Q11)),ISNUMBER(SEARCH("YouTube",Q11)),ISNUMBER(SEARCH("Instagram",Q11)),ISNUMBER(SEARCH("Google",Q11)),ISNUMBER(SEARCH("store",Q11)),ISNUMBER(SEARCH("two sizes",Q11))),"off_app","in_app")) | AH11: =IF(N11="","",IF(ISNUMBER(SEARCH("coupon",N11))+ISNUMBER(SEARCH("sale",N11))+ISNUMBER(SEARCH("kept-vs-returned",N11))+ISNUMBER(SEARCH("sentence",N11))+ISNUMBER(SEARCH("stays with",N11))+ISNUMBER(SEARCH("side-by-side",N11)),IF(ISNUMBER(SEARCH("kept-vs-returned",N11))+ISNUMBER(SEARCH("sentence",N11))+ISNUMBER(SEARCH("stays with",N11))+ISNUMBER(SEARCH("side-by-side",N11)),"legal_present",IF(ISNUMBER(SEARCH("coupon",N11))+ISNUMBER(SEARCH("sale",N11)),"coupon_only","other")),"other"))
A12: 8/11/2026 9:09:52 | B12: Yes, continue | C12: Yes | D12: Woman | E12: 33–40 | F12: Bengaluru | G12: 15–40 | H12: Yes | I12: A few times a month | J12: I meant to buy it soon | K12: Yes | L12: I’m worried about returns, exchange-only, or a seal tag | M12: Whether I can return or exchange it, Whether the next size exists, Fit on my body / height | N12: Return / seal-tag / exchange-only written as a sentence on the card, A kept-vs-returned story from people my size and height, on the wishlist card | O12: Return policy in words, not an icon, Whether Try and Buy exists on this SKU, How this sat on someone near my height | P12: Yes — but I may buy none | Q12: WhatsApp / send photos to friends or family, YouTube haul / try-on, Visit a store to touch fabric or try a similar cut | R12: Only buy brands I have kept before, Read 50+ reviews on the product page, Order two sizes, Wait for a sale so a failed return hurts less | S12: Yes | T12: 4 | U12: 5 | V12: 3 | W12: 2 | X12: 2 | Y12: A shopping list I intend to buy from | Z12: Under 5'2" | AA12: M | AB12: No — ethnic runs different | AC12: Mix of workwear and occasion | AE12: =IF(C12="","",IF(AND(D12="Woman",E12="24–32",OR(F12="Bengaluru",F12="Hyderabad",F12="Delhi",F12="Gurugram",F12="Noida",F12="Coimbatore"),OR(G12="15–40",G12="41–80",G12="81+"),H12="Yes",OR(I12="Most days",I12="About weekly")),"YES","NO")) | AF12: =IF(L12="","",IF(ISNUMBER(SEARCH("fit",L12)),"fit",IF(ISNUMBER(SEARCH("return",L12))+ISNUMBER(SEARCH("seal",L12)),"return",IF(ISNUMBER(SEARCH("chart",L12)),"chart",IF(ISNUMBER(SEARCH("choose",L12)),"compare",IF(ISNUMBER(SEARCH("sale",L12)),"sale",IF(ISNUMBER(SEARCH("never",L12)),"bookmark",IF(ISNUMBER(SEARCH("mess",L12)),"clutter",IF(ISNUMBER(SEARCH("wear it",L12)),"occasion",IF(ISNUMBER(SEARCH("quality",L12)),"quality","other")))))))))) | AG12: =IF(Q12="","",IF(OR(ISNUMBER(SEARCH("WhatsApp",Q12)),ISNUMBER(SEARCH("YouTube",Q12)),ISNUMBER(SEARCH("Instagram",Q12)),ISNUMBER(SEARCH("Google",Q12)),ISNUMBER(SEARCH("store",Q12)),ISNUMBER(SEARCH("two sizes",Q12))),"off_app","in_app")) | AH12: =IF(N12="","",IF(ISNUMBER(SEARCH("coupon",N12))+ISNUMBER(SEARCH("sale",N12))+ISNUMBER(SEARCH("kept-vs-returned",N12))+ISNUMBER(SEARCH("sentence",N12))+ISNUMBER(SEARCH("stays with",N12))+ISNUMBER(SEARCH("side-by-side",N12)),IF(ISNUMBER(SEARCH("kept-vs-returned",N12))+ISNUMBER(SEARCH("sentence",N12))+ISNUMBER(SEARCH("stays with",N12))+ISNUMBER(SEARCH("side-by-side",N12)),"legal_present",IF(ISNUMBER(SEARCH("coupon",N12))+ISNUMBER(SEARCH("sale",N12)),"coupon_only","other")),"other"))
A13: 8/11/2026 11:11:18 | B13: Yes, continue | C13: Yes | D13: Woman | E13: 24–32 | F13: Hyderabad | G13: 15–40 | H13: Yes | I13: About weekly | J13: I meant to buy it soon | K13: Yes | L13: I’m worried about returns, exchange-only, or a seal tag | M13: Whether I can return or exchange it, Whether the next size exists, Fit on my body / height | N13: Return / seal-tag / exchange-only written as a sentence on the card, A kept-vs-returned story from people my size and height, on the wishlist card | O13: Return policy in words, not an icon, Whether Try and Buy exists on this SKU, How this sat on someone near my height | P13: Yes — I will buy one of them | Q13: WhatsApp / send photos to friends or family, YouTube haul / try-on, Visit a store to touch fabric or try a similar cut | R13: Only buy brands I have kept before, Read 50+ reviews on the product page, Ask a friend their size in that brand, Wait for a sale so a failed return hurts less | S13: Yes | T13: 4 | U13: 5 | V13: 3 | W13: 2 | X13: 4 | Y13: A shopping list I intend to buy from | Z13: 5'2"–5'5" | AA13: S | AB13: No — ethnic runs different | AC13: Mostly occasion / ethnic | AD13: I have the money. I don’t have another Sunday for a reverse pickup. | AE13: =IF(C13="","",IF(AND(D13="Woman",E13="24–32",OR(F13="Bengaluru",F13="Hyderabad",F13="Delhi",F13="Gurugram",F13="Noida",F13="Coimbatore"),OR(G13="15–40",G13="41–80",G13="81+"),H13="Yes",OR(I13="Most days",I13="About weekly")),"YES","NO")) | AF13: =IF(L13="","",IF(ISNUMBER(SEARCH("fit",L13)),"fit",IF(ISNUMBER(SEARCH("return",L13))+ISNUMBER(SEARCH("seal",L13)),"return",IF(ISNUMBER(SEARCH("chart",L13)),"chart",IF(ISNUMBER(SEARCH("choose",L13)),"compare",IF(ISNUMBER(SEARCH("sale",L13)),"sale",IF(ISNUMBER(SEARCH("never",L13)),"bookmark",IF(ISNUMBER(SEARCH("mess",L13)),"clutter",IF(ISNUMBER(SEARCH("wear it",L13)),"occasion",IF(ISNUMBER(SEARCH("quality",L13)),"quality","other")))))))))) | AG13: =IF(Q13="","",IF(OR(ISNUMBER(SEARCH("WhatsApp",Q13)),ISNUMBER(SEARCH("YouTube",Q13)),ISNUMBER(SEARCH("Instagram",Q13)),ISNUMBER(SEARCH("Google",Q13)),ISNUMBER(SEARCH("store",Q13)),ISNUMBER(SEARCH("two sizes",Q13))),"off_app","in_app")) | AH13: =IF(N13="","",IF(ISNUMBER(SEARCH("coupon",N13))+ISNUMBER(SEARCH("sale",N13))+ISNUMBER(SEARCH("kept-vs-returned",N13))+ISNUMBER(SEARCH("sentence",N13))+ISNUMBER(SEARCH("stays with",N13))+ISNUMBER(SEARCH("side-by-side",N13)),IF(ISNUMBER(SEARCH("kept-vs-returned",N13))+ISNUMBER(SEARCH("sentence",N13))+ISNUMBER(SEARCH("stays with",N13))+ISNUMBER(SEARCH("side-by-side",N13)),"legal_present",IF(ISNUMBER(SEARCH("coupon",N13))+ISNUMBER(SEARCH("sale",N13)),"coupon_only","other")),"other"))
A14: 8/11/2026 13:32:40 | B14: Yes, continue | C14: Yes | D14: Woman | E14: 24–32 | F14: Noida | G14: 41–80 | H14: Yes | I14: Most days | J14: I meant to buy it soon | K14: Yes | L14: I don’t know if it will fit me / this brand’s cut | M14: Fit on my body / height, Which size to pick | N14: A kept-vs-returned story from people my size and height, on the wishlist card, A suggested size that stays with the saved item (not only on the product page), Return / seal-tag / exchange-only written as a sentence on the card | O14: How this sat on someone near my height, Whether people who wear my usual size kept it, Length / crop / rise for my height | P14: Yes — I will buy one of them | Q14: WhatsApp / send photos to friends or family, YouTube haul / try-on | R14: Only buy brands I have kept before, Read 50+ reviews on the product page, Ask a friend their size in that brand | S14: Yes | T14: 5 | U14: 3 | V14: 2 | W14: 2 | X14: 2 | Y14: A shopping list I intend to buy from | Z14: 5'2"–5'5" | AA14: M | AB14: No — ethnic runs different | AC14: Mix of workwear and occasion | AE14: =IF(C14="","",IF(AND(D14="Woman",E14="24–32",OR(F14="Bengaluru",F14="Hyderabad",F14="Delhi",F14="Gurugram",F14="Noida",F14="Coimbatore"),OR(G14="15–40",G14="41–80",G14="81+"),H14="Yes",OR(I14="Most days",I14="About weekly")),"YES","NO")) | AF14: =IF(L14="","",IF(ISNUMBER(SEARCH("fit",L14)),"fit",IF(ISNUMBER(SEARCH("return",L14))+ISNUMBER(SEARCH("seal",L14)),"return",IF(ISNUMBER(SEARCH("chart",L14)),"chart",IF(ISNUMBER(SEARCH("choose",L14)),"compare",IF(ISNUMBER(SEARCH("sale",L14)),"sale",IF(ISNUMBER(SEARCH("never",L14)),"bookmark",IF(ISNUMBER(SEARCH("mess",L14)),"clutter",IF(ISNUMBER(SEARCH("wear it",L14)),"occasion",IF(ISNUMBER(SEARCH("quality",L14)),"quality","other")))))))))) | AG14: =IF(Q14="","",IF(OR(ISNUMBER(SEARCH("WhatsApp",Q14)),ISNUMBER(SEARCH("YouTube",Q14)),ISNUMBER(SEARCH("Instagram",Q14)),ISNUMBER(SEARCH("Google",Q14)),ISNUMBER(SEARCH("store",Q14)),ISNUMBER(SEARCH("two sizes",Q14))),"off_app","in_app")) | AH14: =IF(N14="","",IF(ISNUMBER(SEARCH("coupon",N14))+ISNUMBER(SEARCH("sale",N14))+ISNUMBER(SEARCH("kept-vs-returned",N14))+ISNUMBER(SEARCH("sentence",N14))+ISNUMBER(SEARCH("stays with",N14))+ISNUMBER(SEARCH("side-by-side",N14)),IF(ISNUMBER(SEARCH("kept-vs-returned",N14))+ISNUMBER(SEARCH("sentence",N14))+ISNUMBER(SEARCH("stays with",N14))+ISNUMBER(SEARCH("side-by-side",N14)),"legal_present",IF(ISNUMBER(SEARCH("coupon",N14))+ISNUMBER(SEARCH("sale",N14)),"coupon_only","other")),"other"))
A15: 8/11/2026 15:59:49 | B15: Yes, continue | C15: Yes | D15: Woman | E15: 24–32 | F15: Delhi | G15: 15–40 | H15: Yes | I15: About weekly | J15: I meant to buy it soon | K15: Yes | L15: I’m worried about returns, exchange-only, or a seal tag | M15: Whether I can return or exchange it, Whether the next size exists, Fit on my body / height | N15: Return / seal-tag / exchange-only written as a sentence on the card, A kept-vs-returned story from people my size and height, on the wishlist card | O15: Return policy in words, not an icon, Whether Try and Buy exists on this SKU, How this sat on someone near my height | P15: No | Q15: WhatsApp / send photos to friends or family, YouTube haul / try-on | R15: Only buy brands I have kept before, Read 50+ reviews on the product page, Ask a friend their size in that brand, Wait for a sale so a failed return hurts less | S15: No | T15: 4 | U15: 5 | V15: 3 | W15: 2 | X15: 4 | Y15: A shopping list I intend to buy from | Z15: Under 5'2" | AA15: L | AB15: No — ethnic runs different | AC15: Mostly workwear | AD15: Exchange-only should scream before I get attached. I found it too late. | AE15: =IF(C15="","",IF(AND(D15="Woman",E15="24–32",OR(F15="Bengaluru",F15="Hyderabad",F15="Delhi",F15="Gurugram",F15="Noida",F15="Coimbatore"),OR(G15="15–40",G15="41–80",G15="81+"),H15="Yes",OR(I15="Most days",I15="About weekly")),"YES","NO")) | AF15: =IF(L15="","",IF(ISNUMBER(SEARCH("fit",L15)),"fit",IF(ISNUMBER(SEARCH("return",L15))+ISNUMBER(SEARCH("seal",L15)),"return",IF(ISNUMBER(SEARCH("chart",L15)),"chart",IF(ISNUMBER(SEARCH("choose",L15)),"compare",IF(ISNUMBER(SEARCH("sale",L15)),"sale",IF(ISNUMBER(SEARCH("never",L15)),"bookmark",IF(ISNUMBER(SEARCH("mess",L15)),"clutter",IF(ISNUMBER(SEARCH("wear it",L15)),"occasion",IF(ISNUMBER(SEARCH("quality",L15)),"quality","other")))))))))) | AG15: =IF(Q15="","",IF(OR(ISNUMBER(SEARCH("WhatsApp",Q15)),ISNUMBER(SEARCH("YouTube",Q15)),ISNUMBER(SEARCH("Instagram",Q15)),ISNUMBER(SEARCH("Google",Q15)),ISNUMBER(SEARCH("store",Q15)),ISNUMBER(SEARCH("two sizes",Q15))),"off_app","in_app")) | AH15: =IF(N15="","",IF(ISNUMBER(SEARCH("coupon",N15))+ISNUMBER(SEARCH("sale",N15))+ISNUMBER(SEARCH("kept-vs-returned",N15))+ISNUMBER(SEARCH("sentence",N15))+ISNUMBER(SEARCH("stays with",N15))+ISNUMBER(SEARCH("side-by-side",N15)),IF(ISNUMBER(SEARCH("kept-vs-returned",N15))+ISNUMBER(SEARCH("sentence",N15))+ISNUMBER(SEARCH("stays with",N15))+ISNUMBER(SEARCH("side-by-side",N15)),"legal_present",IF(ISNUMBER(SEARCH("coupon",N15))+ISNUMBER(SEARCH("sale",N15)),"coupon_only","other")),"other"))
A16: 8/12/2026 2:49:21 | B16: Yes, continue | C16: Yes | D16: Woman | E16: 24–32 | F16: Coimbatore | G16: 15–40 | H16: Yes | I16: Most days | J16: I meant to buy it soon | K16: Yes | L16: I’m worried about returns, exchange-only, or a seal tag | M16: Whether I can return or exchange it, Whether the next size exists, Fit on my body / height | N16: Return / seal-tag / exchange-only written as a sentence on the card, A kept-vs-returned story from people my size and height, on the wishlist card, A coupon or sale | O16: Return policy in words, not an icon, Whether Try and Buy exists on this SKU, How this sat on someone near my height | P16: No | Q16: WhatsApp / send photos to friends or family, YouTube haul / try-on, Visit a store to touch fabric or try a similar cut | R16: Only buy brands I have kept before, Read 50+ reviews on the product page, Ask a friend their size in that brand, Order two sizes, Wait for a sale so a failed return hurts less | S16: Yes | T16: 4 | U16: 5 | V16: 3 | W16: 2 | X16: 4 | Y16: A shopping list I intend to buy from | Z16: 5'5"–5'8" | AA16: XS | AB16: No — ethnic runs different | AC16: Mix of workwear and occasion | AD16: Seal tag means I cannot actually try it. So I don’t buy from a photo. | AE16: =IF(C16="","",IF(AND(D16="Woman",E16="24–32",OR(F16="Bengaluru",F16="Hyderabad",F16="Delhi",F16="Gurugram",F16="Noida",F16="Coimbatore"),OR(G16="15–40",G16="41–80",G16="81+"),H16="Yes",OR(I16="Most days",I16="About weekly")),"YES","NO")) | AF16: =IF(L16="","",IF(ISNUMBER(SEARCH("fit",L16)),"fit",IF(ISNUMBER(SEARCH("return",L16))+ISNUMBER(SEARCH("seal",L16)),"return",IF(ISNUMBER(SEARCH("chart",L16)),"chart",IF(ISNUMBER(SEARCH("choose",L16)),"compare",IF(ISNUMBER(SEARCH("sale",L16)),"sale",IF(ISNUMBER(SEARCH("never",L16)),"bookmark",IF(ISNUMBER(SEARCH("mess",L16)),"clutter",IF(ISNUMBER(SEARCH("wear it",L16)),"occasion",IF(ISNUMBER(SEARCH("quality",L16)),"quality","other")))))))))) | AG16: =IF(Q16="","",IF(OR(ISNUMBER(SEARCH("WhatsApp",Q16)),ISNUMBER(SEARCH("YouTube",Q16)),ISNUMBER(SEARCH("Instagram",Q16)),ISNUMBER(SEARCH("Google",Q16)),ISNUMBER(SEARCH("store",Q16)),ISNUMBER(SEARCH("two sizes",Q16))),"off_app","in_app")) | AH16: =IF(N16="","",IF(ISNUMBER(SEARCH("coupon",N16))+ISNUMBER(SEARCH("sale",N16))+ISNUMBER(SEARCH("kept-vs-returned",N16))+ISNUMBER(SEARCH("sentence",N16))+ISNUMBER(SEARCH("stays with",N16))+ISNUMBER(SEARCH("side-by-side",N16)),IF(ISNUMBER(SEARCH("kept-vs-returned",N16))+ISNUMBER(SEARCH("sentence",N16))+ISNUMBER(SEARCH("stays with",N16))+ISNUMBER(SEARCH("side-by-side",N16)),"legal_present",IF(ISNUMBER(SEARCH("coupon",N16))+ISNUMBER(SEARCH("sale",N16)),"coupon_only","other")),"other"))
A17: 8/12/2026 9:02:33 | B17: Yes, continue | C17: Yes | D17: Woman | E17: 24–32 | F17: Noida | G17: 15–40 | H17: Yes | I17: Most days | J17: For an occasion / event coming up | K17: Maybe | L17: I’m not sure when or where I’d wear it | M17: Occasion / office-appropriateness | N17: A kept-vs-returned story from people my size and height, on the wishlist card, A suggested size that stays with the saved item (not only on the product page) | O17: How this sat on someone near my height, Return policy in words, not an icon | P17: No | Q17: WhatsApp / send photos to friends or family, YouTube haul / try-on | R17: Only buy brands I have kept before, Read 50+ reviews on the product page, Ask a friend their size in that brand, Don’t buy — leave it wishlisted | S17: Yes | T17: 3 | U17: 3 | V17: 2 | W17: 5 | X17: 4 | Y17: A mix | Z17: 5'2"–5'5" | AA17: M | AB17: No — ethnic runs different | AC17: Mix of workwear and occasion | AD17: Function is in three weeks. Dupatta length and seal tag — that’s the stall. | AE17: =IF(C17="","",IF(AND(D17="Woman",E17="24–32",OR(F17="Bengaluru",F17="Hyderabad",F17="Delhi",F17="Gurugram",F17="Noida",F17="Coimbatore"),OR(G17="15–40",G17="41–80",G17="81+"),H17="Yes",OR(I17="Most days",I17="About weekly")),"YES","NO")) | AF17: =IF(L17="","",IF(ISNUMBER(SEARCH("fit",L17)),"fit",IF(ISNUMBER(SEARCH("return",L17))+ISNUMBER(SEARCH("seal",L17)),"return",IF(ISNUMBER(SEARCH("chart",L17)),"chart",IF(ISNUMBER(SEARCH("choose",L17)),"compare",IF(ISNUMBER(SEARCH("sale",L17)),"sale",IF(ISNUMBER(SEARCH("never",L17)),"bookmark",IF(ISNUMBER(SEARCH("mess",L17)),"clutter",IF(ISNUMBER(SEARCH("wear it",L17)),"occasion",IF(ISNUMBER(SEARCH("quality",L17)),"quality","other")))))))))) | AG17: =IF(Q17="","",IF(OR(ISNUMBER(SEARCH("WhatsApp",Q17)),ISNUMBER(SEARCH("YouTube",Q17)),ISNUMBER(SEARCH("Instagram",Q17)),ISNUMBER(SEARCH("Google",Q17)),ISNUMBER(SEARCH("store",Q17)),ISNUMBER(SEARCH("two sizes",Q17))),"off_app","in_app")) | AH17: =IF(N17="","",IF(ISNUMBER(SEARCH("coupon",N17))+ISNUMBER(SEARCH("sale",N17))+ISNUMBER(SEARCH("kept-vs-returned",N17))+ISNUMBER(SEARCH("sentence",N17))+ISNUMBER(SEARCH("stays with",N17))+ISNUMBER(SEARCH("side-by-side",N17)),IF(ISNUMBER(SEARCH("kept-vs-returned",N17))+ISNUMBER(SEARCH("sentence",N17))+ISNUMBER(SEARCH("stays with",N17))+ISNUMBER(SEARCH("side-by-side",N17)),"legal_present",IF(ISNUMBER(SEARCH("coupon",N17))+ISNUMBER(SEARCH("sale",N17)),"coupon_only","other")),"other"))
A18: 8/12/2026 10:06:49 | B18: Yes, continue | C18: Yes | D18: Woman | E18: 24–32 | F18: Pune | G18: 15–40 | H18: Yes | I18: Rarely | J18: I meant to buy it soon | K18: Yes | L18: I don’t know if it will fit me / this brand’s cut | M18: Fit on my body / height, Which size to pick, Whether I can return or exchange it | N18: A kept-vs-returned story from people my size and height, on the wishlist card, A suggested size that stays with the saved item (not only on the product page), A friend telling me to buy it | O18: How this sat on someone near my height, Whether people who wear my usual size kept it, Length / crop / rise for my height | P18: No | Q18: WhatsApp / send photos to friends or family, YouTube haul / try-on, Google size charts or reviews | R18: Only buy brands I have kept before, Read 50+ reviews on the product page | S18: Yes | T18: 5 | U18: 3 | V18: 2 | W18: 2 | X18: 4 | Y18: A shopping list I intend to buy from | Z18: 5'2"–5'5" | AA18: M | AB18: No — ethnic runs different | AC18: Mix of workwear and occasion | AD18: Reviews split on size up. I will not play that with a ₹3,000 dress. | AE18: =IF(C18="","",IF(AND(D18="Woman",E18="24–32",OR(F18="Bengaluru",F18="Hyderabad",F18="Delhi",F18="Gurugram",F18="Noida",F18="Coimbatore"),OR(G18="15–40",G18="41–80",G18="81+"),H18="Yes",OR(I18="Most days",I18="About weekly")),"YES","NO")) | AF18: =IF(L18="","",IF(ISNUMBER(SEARCH("fit",L18)),"fit",IF(ISNUMBER(SEARCH("return",L18))+ISNUMBER(SEARCH("seal",L18)),"return",IF(ISNUMBER(SEARCH("chart",L18)),"chart",IF(ISNUMBER(SEARCH("choose",L18)),"compare",IF(ISNUMBER(SEARCH("sale",L18)),"sale",IF(ISNUMBER(SEARCH("never",L18)),"bookmark",IF(ISNUMBER(SEARCH("mess",L18)),"clutter",IF(ISNUMBER(SEARCH("wear it",L18)),"occasion",IF(ISNUMBER(SEARCH("quality",L18)),"quality","other")))))))))) | AG18: =IF(Q18="","",IF(OR(ISNUMBER(SEARCH("WhatsApp",Q18)),ISNUMBER(SEARCH("YouTube",Q18)),ISNUMBER(SEARCH("Instagram",Q18)),ISNUMBER(SEARCH("Google",Q18)),ISNUMBER(SEARCH("store",Q18)),ISNUMBER(SEARCH("two sizes",Q18))),"off_app","in_app")) | AH18: =IF(N18="","",IF(ISNUMBER(SEARCH("coupon",N18))+ISNUMBER(SEARCH("sale",N18))+ISNUMBER(SEARCH("kept-vs-returned",N18))+ISNUMBER(SEARCH("sentence",N18))+ISNUMBER(SEARCH("stays with",N18))+ISNUMBER(SEARCH("side-by-side",N18)),IF(ISNUMBER(SEARCH("kept-vs-returned",N18))+ISNUMBER(SEARCH("sentence",N18))+ISNUMBER(SEARCH("stays with",N18))+ISNUMBER(SEARCH("side-by-side",N18)),"legal_present",IF(ISNUMBER(SEARCH("coupon",N18))+ISNUMBER(SEARCH("sale",N18)),"coupon_only","other")),"other"))
A19: 8/12/2026 17:06:23 | B19: Yes, continue | C19: Yes | D19: Woman | E19: 24–32 | F19: Delhi | G19: 15–40 | H19: Yes | I19: About weekly | J19: Waiting for a sale or price drop | K19: Yes | L19: I’m waiting for a sale or discount | M19: Price, Whether I can return or exchange it | N19: A coupon or sale, Return / seal-tag / exchange-only written as a sentence on the card, A kept-vs-returned story from people my size and height, on the wishlist card | O19: How this sat on someone near my height, Return policy in words, not an icon | P19: Yes — I will buy one of them | Q19: WhatsApp / send photos to friends or family, YouTube haul / try-on, Google size charts or reviews | R19: Only buy brands I have kept before, Read 50+ reviews on the product page, Wait for a sale so a failed return hurts less, Don’t buy — leave it wishlisted | S19: Yes | T19: 3 | U19: 4 | V19: 5 | W19: 2 | X19: 4 | Y19: A shopping list I intend to buy from | Z19: 5'5"–5'8" | AA19: M | AB19: No — ethnic runs different | AC19: Mix of workwear and occasion | AD19: Discounted plus nasty returns. I saved thinking both. Only one was true. | AE19: =IF(C19="","",IF(AND(D19="Woman",E19="24–32",OR(F19="Bengaluru",F19="Hyderabad",F19="Delhi",F19="Gurugram",F19="Noida",F19="Coimbatore"),OR(G19="15–40",G19="41–80",G19="81+"),H19="Yes",OR(I19="Most days",I19="About weekly")),"YES","NO")) | AF19: =IF(L19="","",IF(ISNUMBER(SEARCH("fit",L19)),"fit",IF(ISNUMBER(SEARCH("return",L19))+ISNUMBER(SEARCH("seal",L19)),"return",IF(ISNUMBER(SEARCH("chart",L19)),"chart",IF(ISNUMBER(SEARCH("choose",L19)),"compare",IF(ISNUMBER(SEARCH("sale",L19)),"sale",IF(ISNUMBER(SEARCH("never",L19)),"bookmark",IF(ISNUMBER(SEARCH("mess",L19)),"clutter",IF(ISNUMBER(SEARCH("wear it",L19)),"occasion",IF(ISNUMBER(SEARCH("quality",L19)),"quality","other")))))))))) | AG19: =IF(Q19="","",IF(OR(ISNUMBER(SEARCH("WhatsApp",Q19)),ISNUMBER(SEARCH("YouTube",Q19)),ISNUMBER(SEARCH("Instagram",Q19)),ISNUMBER(SEARCH("Google",Q19)),ISNUMBER(SEARCH("store",Q19)),ISNUMBER(SEARCH("two sizes",Q19))),"off_app","in_app")) | AH19: =IF(N19="","",IF(ISNUMBER(SEARCH("coupon",N19))+ISNUMBER(SEARCH("sale",N19))+ISNUMBER(SEARCH("kept-vs-returned",N19))+ISNUMBER(SEARCH("sentence",N19))+ISNUMBER(SEARCH("stays with",N19))+ISNUMBER(SEARCH("side-by-side",N19)),IF(ISNUMBER(SEARCH("kept-vs-returned",N19))+ISNUMBER(SEARCH("sentence",N19))+ISNUMBER(SEARCH("stays with",N19))+ISNUMBER(SEARCH("side-by-side",N19)),"legal_present",IF(ISNUMBER(SEARCH("coupon",N19))+ISNUMBER(SEARCH("sale",N19)),"coupon_only","other")),"other"))
A20: 8/13/2026 1:08:13 | B20: Yes, continue | C20: Yes | D20: Woman | E20: 24–32 | F20: Hyderabad | G20: 15–40 | H20: Yes | I20: About weekly | J20: I meant to buy it soon | K20: Yes | L20: I’m worried about returns, exchange-only, or a seal tag | M20: Whether I can return or exchange it, Whether the next size exists, Fit on my body / height | N20: Return / seal-tag / exchange-only written as a sentence on the card, A kept-vs-returned story from people my size and height, on the wishlist card | O20: Return policy in words, not an icon, Whether Try and Buy exists on this SKU, How this sat on someone near my height | P20: Yes — I will buy one of them | Q20: WhatsApp / send photos to friends or family, YouTube haul / try-on | R20: Only buy brands I have kept before, Read 50+ reviews on the product page, Ask a friend their size in that brand, Wait for a sale so a failed return hurts less | S20: Not sure | T20: 4 | U20: 5 | V20: 3 | W20: 2 | X20: 2 | Y20: A shopping list I intend to buy from | Z20: Under 5'2" | AA20: M | AB20: Yes, same letter | AC20: Mostly occasion / ethnic | AD20: Pickup didn’t come, window expired. Now I only heart things. | AE20: =IF(C20="","",IF(AND(D20="Woman",E20="24–32",OR(F20="Bengaluru",F20="Hyderabad",F20="Delhi",F20="Gurugram",F20="Noida",F20="Coimbatore"),OR(G20="15–40",G20="41–80",G20="81+"),H20="Yes",OR(I20="Most days",I20="About weekly")),"YES","NO")) | AF20: =IF(L20="","",IF(ISNUMBER(SEARCH("fit",L20)),"fit",IF(ISNUMBER(SEARCH("return",L20))+ISNUMBER(SEARCH("seal",L20)),"return",IF(ISNUMBER(SEARCH("chart",L20)),"chart",IF(ISNUMBER(SEARCH("choose",L20)),"compare",IF(ISNUMBER(SEARCH("sale",L20)),"sale",IF(ISNUMBER(SEARCH("never",L20)),"bookmark",IF(ISNUMBER(SEARCH("mess",L20)),"clutter",IF(ISNUMBER(SEARCH("wear it",L20)),"occasion",IF(ISNUMBER(SEARCH("quality",L20)),"quality","other")))))))))) | AG20: =IF(Q20="","",IF(OR(ISNUMBER(SEARCH("WhatsApp",Q20)),ISNUMBER(SEARCH("YouTube",Q20)),ISNUMBER(SEARCH("Instagram",Q20)),ISNUMBER(SEARCH("Google",Q20)),ISNUMBER(SEARCH("store",Q20)),ISNUMBER(SEARCH("two sizes",Q20))),"off_app","in_app")) | AH20: =IF(N20="","",IF(ISNUMBER(SEARCH("coupon",N20))+ISNUMBER(SEARCH("sale",N20))+ISNUMBER(SEARCH("kept-vs-returned",N20))+ISNUMBER(SEARCH("sentence",N20))+ISNUMBER(SEARCH("stays with",N20))+ISNUMBER(SEARCH("side-by-side",N20)),IF(ISNUMBER(SEARCH("kept-vs-returned",N20))+ISNUMBER(SEARCH("sentence",N20))+ISNUMBER(SEARCH("stays with",N20))+ISNUMBER(SEARCH("side-by-side",N20)),"legal_present",IF(ISNUMBER(SEARCH("coupon",N20))+ISNUMBER(SEARCH("sale",N20)),"coupon_only","other")),"other"))
A21: 8/13/2026 1:43:49 | B21: Yes, continue | C21: Yes | D21: Woman | E21: 24–32 | F21: Delhi | G21: 15–40 | H21: Yes | I21: About weekly | J21: I just liked it — not sure I’ll buy | K21: No | L21: I was never really going to buy it | M21: Nothing — I was just bookmarking | N21: Nothing — I don’t intend to buy it | O21: I have everything I need | P21: No | Q21: Instagram | R21: Don’t buy — leave it wishlisted | S21: Not sure | T21: 2 | U21: 2 | V21: 2 | W21: 2 | X21: 3 | Y21: A moodboard / Pinterest | Z21: Under 5'2" | AA21: S | AB21: Yes, same letter | AC21: Mix of workwear and occasion | AD21: Don’t convert my moodboard. Half of this list is pretty, not a cart. | AE21: =IF(C21="","",IF(AND(D21="Woman",E21="24–32",OR(F21="Bengaluru",F21="Hyderabad",F21="Delhi",F21="Gurugram",F21="Noida",F21="Coimbatore"),OR(G21="15–40",G21="41–80",G21="81+"),H21="Yes",OR(I21="Most days",I21="About weekly")),"YES","NO")) | AF21: =IF(L21="","",IF(ISNUMBER(SEARCH("fit",L21)),"fit",IF(ISNUMBER(SEARCH("return",L21))+ISNUMBER(SEARCH("seal",L21)),"return",IF(ISNUMBER(SEARCH("chart",L21)),"chart",IF(ISNUMBER(SEARCH("choose",L21)),"compare",IF(ISNUMBER(SEARCH("sale",L21)),"sale",IF(ISNUMBER(SEARCH("never",L21)),"bookmark",IF(ISNUMBER(SEARCH("mess",L21)),"clutter",IF(ISNUMBER(SEARCH("wear it",L21)),"occasion",IF(ISNUMBER(SEARCH("quality",L21)),"quality","other")))))))))) | AG21: =IF(Q21="","",IF(OR(ISNUMBER(SEARCH("WhatsApp",Q21)),ISNUMBER(SEARCH("YouTube",Q21)),ISNUMBER(SEARCH("Instagram",Q21)),ISNUMBER(SEARCH("Google",Q21)),ISNUMBER(SEARCH("store",Q21)),ISNUMBER(SEARCH("two sizes",Q21))),"off_app","in_app")) | AH21: =IF(N21="","",IF(ISNUMBER(SEARCH("coupon",N21))+ISNUMBER(SEARCH("sale",N21))+ISNUMBER(SEARCH("kept-vs-returned",N21))+ISNUMBER(SEARCH("sentence",N21))+ISNUMBER(SEARCH("stays with",N21))+ISNUMBER(SEARCH("side-by-side",N21)),IF(ISNUMBER(SEARCH("kept-vs-returned",N21))+ISNUMBER(SEARCH("sentence",N21))+ISNUMBER(SEARCH("stays with",N21))+ISNUMBER(SEARCH("side-by-side",N21)),"legal_present",IF(ISNUMBER(SEARCH("coupon",N21))+ISNUMBER(SEARCH("sale",N21)),"coupon_only","other")),"other"))
A22: 8/13/2026 6:32:09 | B22: Yes, continue | C22: Yes | D22: Woman | E22: 24–32 | F22: Mumbai | G22: 15–40 | H22: Yes | I22: Most days | J22: I meant to buy it soon | K22: Yes | L22: I’m worried about returns, exchange-only, or a seal tag | M22: Whether I can return or exchange it, Whether the next size exists, Fit on my body / height | N22: Return / seal-tag / exchange-only written as a sentence on the card, A kept-vs-returned story from people my size and height, on the wishlist card, A coupon or sale | O22: Return policy in words, not an icon, Whether Try and Buy exists on this SKU, How this sat on someone near my height | P22: Yes — but I may buy none | Q22: WhatsApp / send photos to friends or family, YouTube haul / try-on, Instagram | R22: Only buy brands I have kept before, Read 50+ reviews on the product page, Ask a friend their size in that brand, Wait for a sale so a failed return hurts less, Don’t buy — leave it wishlisted | S22: Yes | T22: 4 | U22: 5 | V22: 3 | W22: 2 | X22: 2 | Y22: A shopping list I intend to buy from | Z22: 5'5"–5'8" | AA22: M | AB22: Yes, same letter | AC22: Mostly workwear | AD22: I have the money. I don’t have another Sunday for a reverse pickup. | AE22: =IF(C22="","",IF(AND(D22="Woman",E22="24–32",OR(F22="Bengaluru",F22="Hyderabad",F22="Delhi",F22="Gurugram",F22="Noida",F22="Coimbatore"),OR(G22="15–40",G22="41–80",G22="81+"),H22="Yes",OR(I22="Most days",I22="About weekly")),"YES","NO")) | AF22: =IF(L22="","",IF(ISNUMBER(SEARCH("fit",L22)),"fit",IF(ISNUMBER(SEARCH("return",L22))+ISNUMBER(SEARCH("seal",L22)),"return",IF(ISNUMBER(SEARCH("chart",L22)),"chart",IF(ISNUMBER(SEARCH("choose",L22)),"compare",IF(ISNUMBER(SEARCH("sale",L22)),"sale",IF(ISNUMBER(SEARCH("never",L22)),"bookmark",IF(ISNUMBER(SEARCH("mess",L22)),"clutter",IF(ISNUMBER(SEARCH("wear it",L22)),"occasion",IF(ISNUMBER(SEARCH("quality",L22)),"quality","other")))))))))) | AG22: =IF(Q22="","",IF(OR(ISNUMBER(SEARCH("WhatsApp",Q22)),ISNUMBER(SEARCH("YouTube",Q22)),ISNUMBER(SEARCH("Instagram",Q22)),ISNUMBER(SEARCH("Google",Q22)),ISNUMBER(SEARCH("store",Q22)),ISNUMBER(SEARCH("two sizes",Q22))),"off_app","in_app")) | AH22: =IF(N22="","",IF(ISNUMBER(SEARCH("coupon",N22))+ISNUMBER(SEARCH("sale",N22))+ISNUMBER(SEARCH("kept-vs-returned",N22))+ISNUMBER(SEARCH("sentence",N22))+ISNUMBER(SEARCH("stays with",N22))+ISNUMBER(SEARCH("side-by-side",N22)),IF(ISNUMBER(SEARCH("kept-vs-returned",N22))+ISNUMBER(SEARCH("sentence",N22))+ISNUMBER(SEARCH("stays with",N22))+ISNUMBER(SEARCH("side-by-side",N22)),"legal_present",IF(ISNUMBER(SEARCH("coupon",N22))+ISNUMBER(SEARCH("sale",N22)),"coupon_only","other")),"other"))
